Workbook

Sheet Dashboard & Analytics
A1: PORTFOLIO & EARNINGS WATCHLIST DASHBOARD
A2: Executive overview, market capitalization mix, sentiment tally, and sectoral distribution
A4: TOTAL STOCKS TRACKED | C4: SCHEDULED EARNINGS | E4: BULLISH SIGNALS (↑ / ↑↑) | G4: BEARISH / CAUTION (↓) | I4: PRE-IPO / UNLISTED
A5: =COUNTA('Master Watchlist'!C5:C73) | C5: =COUNTIF('Master Watchlist'!G5:G73, "Scheduled Date") | E5: =COUNTIF('Master Watchlist'!G5:G73, "*Bullish*") | G5: =COUNTIF('Master Watchlist'!G5:G73, "*Bearish*") | I5: =COUNTIF('Master Watchlist'!F5:F73, "IPO / Unlisted")
A8: Market Cap Breakdown | E8: Sentiment / Setup Status Tally
A9: Category | B9: Stock Count | C9: % of Total | E9: Status / Signal | F9: Stock Count | G9: % of Total
A10: Large Cap | B10: =COUNTIF('Master Watchlist'!$F$5:$F$73, "Large Cap") | C10: =B10/$B$14 | E10: Strong Bullish (↑↑) | F10: =COUNTIF('Master Watchlist'!$G$5:$G$73, "Strong Bullish") | G10: =F10/$F$15
A11: Mid Cap | B11: =COUNTIF('Master Watchlist'!$F$5:$F$73, "Mid Cap") | C11: =B11/$B$14 | E11: Bullish Setup (↑) | F11: =COUNTIF('Master Watchlist'!$G$5:$G$73, "Bullish") | G11: =F11/$F$15
A12: Small Cap | B12: =COUNTIF('Master Watchlist'!$F$5:$F$73, "Small Cap") | C12: =B12/$B$14 | E12: Scheduled Earnings Focus | F12: =COUNTIF('Master Watchlist'!$G$5:$G$73, "Scheduled Date") | G12: =F12/$F$15
A13: IPO / Unlisted | B13: =COUNTIF('Master Watchlist'!$F$5:$F$73, "IPO / Unlisted") | C13: =B13/$B$14 | E13: Bearish / Correction (↓) | F13: =COUNTIF('Master Watchlist'!$G$5:$G$73, "Bearish") | G13: =F13/$F$15
A14: Total | B14: =SUM(B10:B13) | C14: =SUM(C10:C13) | E14: Neutral / Watchlist Tracking | F14: =COUNTIF('Master Watchlist'!$G$5:$G$73, "Watchlist") + COUNTIF('Master Watchlist'!$G$5:$G$73, "Neutral") | G14: =F14/$F$15
E15: Total | F15: =SUM(F10:F14) | G15: =SUM(G10:G14)
A17: Key Sector Concentration
A18: Thematic Sector | B18: Stock Count | C18: % Share
A19: Renewables & Clean Energy | B19: 11 | C19: =B19/$B$28
A20: Defence, Aerospace & Marine | B20: 8 | C20: =B20/$B$28
A21: Railways & Infra EPC | B21: 6 | C21: =B21/$B$28
A22: Electronics, EMS & Tech | B22: 5 | C22: =B22/$B$28
A23: Automotive, EV & Components | B23: 5 | C23: =B23/$B$28
A24: Banking, NBFC & Exchanges | B24: 9 | C24: =B24/$B$28
A25: Real Estate & Co-working | B25: 4 | C25: =B25/$B$28
A26: Metals, Mining & Manufacturing | B26: 5 | C26: =B26/$B$28
A27: Healthcare, Media & Retail | B27: 16 | C27: =B27/$B$28
A28: Total | B28: =SUM(B19:B27) | C28: =SUM(C19:C27)

Sheet Master Watchlist
A1: INDIAN EQUITIES - MASTER WATCHLIST & Q3 RESULTS TRACKER
A2: Complete digitised intelligence from handwritten watchlist • Dec-Q3 Quarter Corporate Calendar, Technical Setups & IPO Pipeline
A4: S.No | B4: Handwritten Ref | C4: Company Name | D4: NSE Symbol | E4: Sector / Industry | F4: Market Cap | G4: Technical / Event Status | H4: Earnings Date | I4: Event Date (ISO) | J4: Signal / Note Details | K4: Core Growth Trigger
A5: 1 | B5: BSE | C5: BSE Limited | D5: BSE | E5: Capital Markets & Exchanges | F5: Mid Cap | G5: Scheduled Date | H5: 09-Feb | I5: 2026-02-09 | J5: Q3 Earnings Announcement | K5: Exchange volumes & transaction revenue
A6: 2 | B6: Cochin | C6: Cochin Shipyard Ltd | D6: COCHINSHIP | E6: Defence & Shipbuilding | F6: Mid Cap | G6: Scheduled Date | H6: 28-Jan | I6: 2026-01-28 | J6: Q3 Earnings Announcement | K6: Naval defence orderbook execution & margin trends
A7: 3 | B7: GRSE | C7: Garden Reach Shipbuilders & Engineers Ltd | D7: GRSE | E7: Defence & Shipbuilding | F7: Small Cap | G7: Scheduled Date | H7: 28-Jan | I7: 2026-01-28 | J7: Q3 Earnings Announcement | K7: Warship delivery timelines & export order pipeline
A8: 4 | B8: BDL | C8: Bharat Dynamics Ltd | D8: BDL | E8: Defence & Aerospace | F8: Mid Cap | G8: Scheduled Date | H8: 31-Jan | I8: 2026-01-31 | J8: Q3 Earnings Announcement | K8: Missile supply schedules & export contracts
A9: 5 | B9: DCB Bank | C9: DCB Bank Ltd | D9: DCBBANK | E9: Banking & Financials | F9: Small Cap | G9: Bullish | H9: Watchlist | I9: 2026-02-01 | J9: Bullish Setup (Up Arrow) | K9: Retail credit growth, NIMs & asset quality stability
A10: 6 | B10: JK Paper | C10: JK Paper Ltd | D10: JKPAPER | E10: Paper & Forest Products | F10: Small Cap | G10: Scheduled Date | H10: 05-Feb | I10: 2026-02-05 | J10: Q3 Earnings Announcement | K10: Wood/raw material input costs & realization margins
A11: 7 | B11: Tata Motor PV | C11: Tata Motors Ltd (PV / EV) | D11: TATAMOTORS | E11: Automobiles & EV | F11: Large Cap | G11: Scheduled Date | H11: 05-Feb | I11: 2026-02-05 | J11: Q3 Earnings Announcement | K11: Passenger vehicle EV sales trajectory & JLR profitability
A12: 8 | B12: BEL | C12: Bharat Electronics Ltd | D12: BEL | E12: Defence Electronics | F12: Large Cap | G12: Bullish | H12: 28-Jan | I12: 2026-01-28 | J12: Q3 Earnings + Bullish Setup | K12: Radar/avionics domestic order inflows & indigenous execution
A13: 9 | B13: HUDCO | C13: Housing & Urban Development Corp Ltd | D13: HUDCO | E13: Housing & Infra Finance / NBFC | F13: Mid Cap | G13: Scheduled Date | H13: 29-Jan | I13: 2026-01-29 | J13: Q3 Earnings Announcement | K13: Urban housing loan disbursements & low NPA profile
A14: 10 | B14: REC | C14: REC Limited | D14: RECLTD | E14: Power Finance / NBFC | F14: Large Cap | G14: Scheduled Date | H14: 29-Jan | I14: 2026-01-29 | J14: Q3 Earnings Announcement | K14: Power project refinancing & renewable book expansion
A15: 11 | B15: MCX | C15: Multi Commodity Exchange of India Ltd | D15: MCX | E15: Capital Markets & Exchanges | F15: Mid Cap | G15: Strong Bullish | H15: Today | I15: 2026-01-27 | J15: Today's Result + Double Bullish | K15: Surging options trading volume & tech migration benefits
A16: 12 | B16: Trent | C16: Trent Ltd | D16: TRENT | E16: Consumer Retail & Fashion | F16: Large Cap | G16: Scheduled Date | H16: 04-Feb | I16: 2026-02-04 | J16: Q3 Earnings Announcement | K16: Zudio & Westside same-store sales growth (SSSG)
... A22: 18 | B22: Godrej Agro/Prop | C22: Godrej Properties / Godrej Agrovet | D22: GODREJPROP | E22: Real Estate & Agri-Business | F22: Large Cap | G22: Scheduled Date | H22: 05-Feb | I22: 2026-02-05 | J22: Q3 Earnings Announcement | K22: Pre-sales booking momentum & new land parcel additions
A23: 19 | B23: PGEL | C23: PG Electroplast Ltd | D23: PGEL | E23: Consumer Electronics & EMS | F23: Mid Cap | G23: Watchlist | H23: Watchlist | J23: EMS Growth Tracking | K23: Room AC & consumer durable contract manufacturing scale
A24: 20 | B24: INA | C24: Insolation Energy Ltd | D24: INA | E24: Renewable Energy / Solar | F24: Small Cap | G24: Watchlist | H24: Watchlist | J24: Solar Module Expansion | K24: Solar panel manufacturing capacity additions & ALMM orders
A25: 21 | B25: Ather Energy | C25: Ather Energy Ltd | D25: ATHER (Pre-IPO) | E25: Automobiles & EV | F25: IPO / Unlisted | G25: Watchlist | H25: IPO Watch | J25: Upcoming Electric 2W IPO | K25: Two-wheeler EV market share & battery plant ramp-up
A26: 22 | B26: Saatvik Energy | C26: Saatvik Green Energy Ltd | D26: SAATVIK (Pre-IPO) | E26: Renewable Energy / Solar | F26: IPO / Unlisted | G26: Watchlist | H26: IPO Watch | J26: Upcoming Solar Manufacturing IPO | K26: High-efficiency TOPCon solar module order pipeline
A27: 23 | B27: Waaree RTL | C27: Waaree Renewable Technologies Ltd | D27: WAAREERTL | E27: Renewable Energy / Solar EPC | F27: Small Cap | G27: Strong Bullish | H27: Watchlist | J27: Double Bullish (Up Arrows) | K27: Utility-scale ground mount solar EPC contract pipeline
A28: 24 | B28: Motilal Oswal | C28: Motilal Oswal Financial Services Ltd | D28: MOTILALOFS | E28: Capital Markets & Broking | F28: Mid Cap | G28: Scheduled Date | H28: 27-Jan | I28: 2026-01-27 | J28: Q3 Earnings + Sideways | K28: Broking retail volume, AMC AUM growth & treasury gains
A29: 25 | B29: Dixon | C29: Dixon Technologies (India) Ltd | D29: DIXON | E29: Consumer Electronics & EMS | F29: Large Cap | G29: Scheduled Date | H29: 29-Jan | I29: 2026-01-29 | J29: Q3 Earnings Announcement | K29: Mobile phone assembly scale-up & IT hardware PLI benefits
A30: 26 | B30: Titagarh | C30: Titagarh Rail Systems Ltd | D30: TITAGARH | E30: Railways & Metro | F30: Mid Cap | G30: Watchlist | H30: Watchlist | J30: Rail Infrastructure Theme | K30: Vande Bharat / Metro trainset supply & freight wagon orders
A31: 27 | B31: Lloyds | C31: Lloyds Engineering Works Ltd | D31: LLOYDSENGG | E31: Heavy Engineering & Capital Goods | F31: Mid Cap | G31: Watchlist | H31: Watchlist | J31: Capital Goods Momentum | K31: Marine & infrastructure equipment order book growth
A32: 28 | B32: Suzlon | C32: Suzlon Energy Ltd | D32: SUZLON | E32: Renewable Energy / Wind | F32: Large Cap | G32: Bearish | H32: 05-Feb | I32: 2026-02-05 | J32: Q3 Earnings + Bearish Correction | K32: Wind turbine delivery execution & WTG supply chain health
A33: 29 | B33: Inox Wind | C33: Inox Wind Ltd | D33: INOXWIND | E33: Renewable Energy / Wind | F33: Mid Cap | G33: Watchlist | H33: Watchlist | J33: Wind Energy Order Pipeline | K33: 3.3 MW turbine commercial rollout & debt reduction progress
A34: 30 | B34: HAL | C34: Hindustan Aeronautics Ltd | D34: HAL | E34: Defence & Aerospace | F34: Large Cap | G34: Watchlist | H34: Watchlist | J34: Core Defence Aerospace Play | K34: Tejas fighter jet engine supply & multi-role helicopter orders
A35: 31 | B35: Mazdock | C35: Mazagon Dock Shipbuilders Ltd | D35: MAZDOCK | E35: Defence & Shipbuilding | F35: Large Cap | G35: Watchlist | H35: Watchlist | J35: Naval Submarine & Warship Play | K35: Next-gen corvette contracts & submarine overhaul cycles
A36: 32 | B36: NMDC | C36: NMDC Ltd | D36: NMDC | E36: Metals & Mining / Iron Ore | F36: Large Cap | G36: Watchlist | H36: Watchlist | J36: Mining Volume & Royalty Play | K36: Iron ore production/sales targets & domestic steel demand
A37: 33 | B37: RVNL | C37: Rail Vikas Nigam Ltd | D37: RVNL | E37: Railways Infrastructure | F37: Large Cap | G37: Scheduled Date | H37: 05-Feb | I37: 2026-02-05 | J37: Q3 Earnings Announcement | K37: Domestic railway track doubling, metro lines & overseas bids
A38: 34 | B38: RailTel | C38: RailTel Corporation of India Ltd | D38: RAILTEL | E38: Telecom & Railways Tech | F38: Small Cap | G38: Watchlist | H38: Watchlist | J38: Railway Telecom & Kavach Play | K38: Telecom optic fibre leasing, Kavach systems & data centers
A39: 35 | B39: Awfis Space | C39: Awfis Space Solutions Ltd | D39: AWFIS | E39: Real Estate & Co-working | F39: Small Cap | G39: Watchlist | H39: Watchlist | J39: Flexible Workspace Expansion | K39: Enterprise seat additions & center occupancy improvements
A40: 36 | B40: HG Infra | C40: H.G. Infra Engineering Ltd | D40: HGINFRA | E40: Infrastructure & Construction | F40: Small Cap | G40: Watchlist | H40: Watchlist | J40: Highways & Solar EPC | K40: HAM highway project awards & diversification into solar EPC
A41: 37 | B41: Authum Inv | C41: Authum Investment & Infrastructure Ltd | D41: AUTHUM | E41: NBFC & Financial Services | F41: Mid Cap | G41: Watchlist | H41: Watchlist | J41: Financial Holding / Value Play | K41: Proprietary equity investment portfolio valuation
A42: 38 | B42: Delhivery | C42: Delhivery Ltd | D42: DELHIVERY | E42: Logistics & Supply Chain | F42: Mid Cap | G42: Bearish | H42: 31-Jan | I42: 2026-01-31 | J42: Q3 Earnings + Downward Trend | K42: Express parcel shipment volumes & truckload network yield
A43: 39 | B43: Ola Electric | C43: Ola Electric Mobility Ltd | D43: OLAELEC | E43: Automobiles & EV | F43: Mid Cap | G43: Watchlist | H43: Watchlist | J43: EV Two-Wheeler Transition | K43: Gen-3 scooter margins, service network & Gigafactory battery
A44: 40 | B44: Kaynes Tech | C44: Kaynes Technology India Ltd | D44: KAYNES | E44: Consumer Electronics & EMS | F44: Mid Cap | G44: Scheduled Date | H44: 05-Feb | I44: 2026-02-05 | J44: Q3 Earnings Announcement | K44: Aerospace/automotive EMS orders & OSAT chip testing facility
A45: 41 | B45: BEML | C45: BEML Ltd | D45: BEML | E45: Defence, Mining & Rail | F45: Small Cap | G45: Watchlist | H45: Watchlist | J45: Rail Coaches & Mining Dumpers | K45: Vande Bharat sleeper trainset production & defence vehicles
A46: 42 | B46: PVR Inox | C46: PVR INOX Ltd | D46: PVRINOX | E46: Media & Entertainment | F46: Mid Cap | G46: Watchlist | H46: Watchlist | J46: Box Office & Occupancy Play | K46: Q3 blockbuster occupancy rates, ATP (Ticket price) & SPH
...

Sheet Q3 Earnings Calendar
A1: Q3 CORPORATE EARNINGS RESULTS CALENDAR
A2: Chronological breakdown of companies with scheduled Q3 board meetings & result dates
A4: Chronological Date | B4: Day / Status | C4: NSE Symbol | D4: Company Name | E4: Sector | F4: Market Cap | G4: Signal on Sheet | H4: Key Earnings Focus
A5: Today | B5: Today | C5: MCX | D5: Multi Commodity Exchange of India Ltd | E5: Capital Markets & Exchanges | F5: Mid Cap | G5: Strong Bullish | H5: Surging options trading volume & tech migration benefits
A6: 27-Jan | B6: Confirmed Q3 | C6: MOTILALOFS | D6: Motilal Oswal Financial Services Ltd | E6: Capital Markets & Broking | F6: Mid Cap | G6: Scheduled Date | H6: Broking retail volume, AMC AUM growth & treasury gains
A7: 28-Jan | B7: Confirmed Q3 | C7: COCHINSHIP | D7: Cochin Shipyard Ltd | E7: Defence & Shipbuilding | F7: Mid Cap | G7: Scheduled Date | H7: Naval defence orderbook execution & margin trends
A8: 28-Jan | B8: Confirmed Q3 | C8: GRSE | D8: Garden Reach Shipbuilders & Engineers Ltd | E8: Defence & Shipbuilding | F8: Small Cap | G8: Scheduled Date | H8: Warship delivery timelines & export order pipeline
A9: 28-Jan | B9: Confirmed Q3 | C9: BEL | D9: Bharat Electronics Ltd | E9: Defence Electronics | F9: Large Cap | G9: Bullish | H9: Radar/avionics domestic order inflows & indigenous execution
A10: 28-Jan | B10: Confirmed Q3 | C10: GVT&D | D10: GE Vernova T&D India Ltd | E10: Power Transmission & Equipment | F10: Mid Cap | G10: Scheduled Date | H10: Grid modernization orders & high-voltage equipment demand
A11: 28-Jan | B11: Confirmed Q3 | C11: SAGILITY | D11: Sagility India Ltd | E11: Healthcare & IT Services | F11: Mid Cap | G11: Scheduled Date | H11: US healthcare payer/provider business process management
A12: 29-Jan | B12: Confirmed Q3 | C12: HUDCO | D12: Housing & Urban Development Corp Ltd | E12: Housing & Infra Finance / NBFC | F12: Mid Cap | G12: Scheduled Date | H12: Urban housing loan disbursements & low NPA profile
A13: 29-Jan | B13: Confirmed Q3 | C13: RECLTD | D13: REC Limited | E13: Power Finance / NBFC | F13: Large Cap | G13: Scheduled Date | H13: Power project refinancing & renewable book expansion
A14: 29-Jan | B14: Confirmed Q3 | C14: TATAMOTORS | D14: Tata Motors Commercial Vehicles | E14: Commercial Vehicles | F14: Large Cap | G14: Scheduled Date | H14: Medium & Heavy Commercial Vehicle (MHCV) tonnage growth
A15: 29-Jan | B15: Confirmed Q3 | C15: DIXON | D15: Dixon Technologies (India) Ltd | E15: Consumer Electronics & EMS | F15: Large Cap | G15: Scheduled Date | H15: Mobile phone assembly scale-up & IT hardware PLI benefits
... A34: 26-Feb | B34: Confirmed Q3 | C34: KALYANKJIL | D34: Kalyan Jewellers India Ltd | E34: Consumer Retail & Jewellery | F34: Large Cap | G34: Scheduled Date | H34: Wedding season jewellery demand & FOCO showroom expansion

Sheet Sectoral Clusters
A1: SECTORAL & THEMATIC BREAKDOWN
A2: Categorized clusters of Renewable Energy, Defence, Rail/Infra, Electronics/EMS, Auto/EV & Finance
A4: Cluster / Sector | B4: NSE Symbol | C4: Company Name | D4: Market Cap | E4: Technical / Sentiment | F4: Earnings Date | G4: Investment Rationale
A5: • RENEWABLE ENERGY & CLEAN TECH (SOLAR / WIND / GREEN NBFC) (13 Stocks)
A6: Renewable Energy & Clean Tech | B6: INA | C6: Insolation Energy Ltd | D6: Small Cap | E6: Watchlist | F6: Watchlist | G6: Solar panel manufacturing capacity additions & ALMM orders
A7: Renewable Energy & Clean Tech | B7: SAATVIK (Pre-IPO) | C7: Saatvik Green Energy Ltd | D7: IPO / Unlisted | E7: Watchlist | F7: IPO Watch | G7: High-efficiency TOPCon solar module order pipeline
A8: Renewable Energy & Clean Tech | B8: WAAREERTL | C8: Waaree Renewable Technologies Ltd | D8: Small Cap | E8: Strong Bullish | F8: Watchlist | G8: Utility-scale ground mount solar EPC contract pipeline
A9: Renewable Energy & Clean Tech | B9: SUZLON | C9: Suzlon Energy Ltd | D9: Large Cap | E9: Bearish | F9: 05-Feb | G9: Wind turbine delivery execution & WTG supply chain health
A10: Renewable Energy & Clean Tech | B10: INOXWIND | C10: Inox Wind Ltd | D10: Mid Cap | E10: Watchlist | F10: Watchlist | G10: 3.3 MW turbine commercial rollout & debt reduction progress
A11: Renewable Energy & Clean Tech | B11: ORIANA | C11: Oriana Power Ltd | D11: Small Cap | E11: Watchlist | F11: Watchlist | G11: Commercial & industrial rooftop/ground-mount solar EPC orders
A12: Renewable Energy & Clean Tech | B12: WAAREE | C12: Waaree Energies Ltd | D12: Large Cap | E12: Strong Bullish | F12: Watchlist | G12: Solar PV module exports to US & domestic capacity expansion
A13: Renewable Energy & Clean Tech | B13: IREDA | C13: Indian Renewable Energy Dev Agency Ltd | D13: Large Cap | E13: Bullish | F13: Watchlist | G13: Green energy loan sanctions, loan book CAGR & zero NPA trend
A14: Renewable Energy & Clean Tech | B14: SWSOLAR | C14: Sterling and Wilson Renewable Energy Ltd | D14: Small Cap | E14: Bearish | F14: Watchlist | G14: International solar EPC execution & unbilled revenue recovery
A15: Renewable Energy & Clean Tech | B15: KPENERGY | C15: KP Energy Ltd | D15: Small Cap | E15: Strong Bullish | F15: Watchlist | G15: Wind energy balance of plant (BoP) execution in Gujarat
A16: Renewable Energy & Clean Tech | B16: VIKRAM (Pre-IPO) | C16: Vikram Solar Ltd | D16: IPO / Unlisted | E16: Strong Bullish | F16: IPO Watch | G16: Upcoming solar cell/module manufacturing IPO
A17: Renewable Energy & Clean Tech | B17: PREMIERENE | C17: Premier Energies Ltd | D17: Mid Cap | E17: Strong Bullish | F17: Watchlist | G17: Solar cell & module manufacturing order book delivery
A18: Renewable Energy & Clean Tech | B18: EMVEE (Pre-IPO) | C18: Emvee Photovoltaic Power Ltd | D18: IPO / Unlisted | E18: Strong Bullish | F18: IPO Watch | G18: Upcoming TOPCon solar cell/module manufacturing IPO
A20: • DEFENCE, AEROSPACE & NAVAL SHIPBUILDING (9 Stocks)
A21: Defence, Aerospace & Naval Shipbuilding | B21: COCHINSHIP | C21: Cochin Shipyard Ltd | D21: Mid Cap | E21: Scheduled Date | F21: 28-Jan | G21: Naval defence orderbook execution & margin trends
A22: Defence, Aerospace & Naval Shipbuilding | B22: GRSE | C22: Garden Reach Shipbuilders & Engineers Ltd | D22: Small Cap | E22: Scheduled Date | F22: 28-Jan | G22: Warship delivery timelines & export order pipeline
A23: Defence, Aerospace & Naval Shipbuilding | B23: BDL | C23: Bharat Dynamics Ltd | D23: Mid Cap | E23: Scheduled Date | F23: 31-Jan | G23: Missile supply schedules & export contracts
A24: Defence, Aerospace & Naval Shipbuilding | B24: BEL | C24: Bharat Electronics Ltd | D24: Large Cap | E24: Bullish | F24: 28-Jan | G24: Radar/avionics domestic order inflows & indigenous execution
A25: Defence, Aerospace & Naval Shipbuilding | B25: HAL | C25: Hindustan Aeronautics Ltd | D25: Large Cap | E25: Watchlist | F25: Watchlist | G25: Tejas fighter jet engine supply & multi-role helicopter orders
A26: Defence, Aerospace & Naval Shipbuilding | B26: MAZDOCK | C26: Mazagon Dock Shipbuilders Ltd | D26: Large Cap | E26: Watchlist | F26: Watchlist | G26: Next-gen corvette contracts & submarine overhaul cycles
A27: Defence, Aerospace & Naval Shipbuilding | B27: BEML | C27: BEML Ltd | D27: Small Cap | E27: Watchlist | F27: Watchlist | G27: Vande Bharat sleeper trainset production & defence vehicles
A28: Defence, Aerospace & Naval Shipbuilding | B28: HBLPOWER | C28: HBL Power Systems Ltd | D28: Mid Cap | E28: Scheduled Date | F28: 07-Feb | G28: Kavach automatic train protection orders & submarine battery
A29: Defence, Aerospace & Naval Shipbuilding | B29: DATAPATTNS | C29: Data Patterns (India) Ltd | D29: Mid Cap | E29: Watchlist | F29: Watchlist | G29: Radars, electronic warfare systems & missile avionics orders
A31: • RAILWAYS & INFRASTRUCTURE ENGINEERING (7 Stocks)
A32: Railways & Infrastructure Engineering | B32: TITAGARH | C32: Titagarh Rail Systems Ltd | D32: Mid Cap | E32: Watchlist | F32: Watchlist | G32: Vande Bharat / Metro trainset supply & freight wagon orders
A33: Railways & Infrastructure Engineering | B33: RVNL | C33: Rail Vikas Nigam Ltd | D33: Large Cap | E33: Scheduled Date | F33: 05-Feb | G33: Domestic railway track doubling, metro lines & overseas bids
A34: Railways & Infrastructure Engineering | B34: RAILTEL | C34: RailTel Corporation of India Ltd | D34: Small Cap | E34: Watchlist | F34: Watchlist | G34: Telecom optic fibre leasing, Kavach systems & data centers
A35: Railways & Infrastructure Engineering | B35: HGINFRA | C35: H.G. Infra Engineering Ltd | D35: Small Cap | E35: Watchlist | F35: Watchlist | G35: HAM highway project awards & diversification into solar EPC
A36: Railways & Infrastructure Engineering | B36: BEML | C36: BEML Ltd | D36: Small Cap | E36: Watchlist | F36: Watchlist | G36: Vande Bharat sleeper trainset production & defence vehicles
A37: Railways & Infrastructure Engineering | B37: IRFC | C37: Indian Railway Finance Corporation Ltd | D37: Large Cap | E37: Bullish | F37: Watchlist | G37: MoR rolling stock leasing lease margin & sovereign safety
A38: Railways & Infrastructure Engineering | B38: HBLPOWER | C38: HBL Power Systems Ltd | D38: Mid Cap | E38: Scheduled Date | F38: 07-Feb | G38: Kavach automatic train protection orders & submarine battery
A40: • ELECTRONICS MANUFACTURING (EMS) & AI SUPERCOMPUTING (5 Stocks)
A41: Electronics Manufacturing | B41: PGEL | C41: PG Electroplast Ltd | D41: Mid Cap | E41: Watchlist | F41: Watchlist | G41: Room AC & consumer durable contract manufacturing scale
A42: Electronics Manufacturing | B42: DIXON | C42: Dixon Technologies (India) Ltd | D42: Large Cap | E42: Scheduled Date | F42: 29-Jan | G42: Mobile phone assembly scale-up & IT hardware PLI benefits
A43: Electronics Manufacturing | B43: KAYNES | C43: Kaynes Technology India Ltd | D43: Mid Cap | E43: Scheduled Date | F43: 05-Feb | G43: Aerospace/automotive EMS orders & OSAT chip testing facility
A44: Electronics Manufacturing | B44: NETWEB | C44: Netweb Technologies India Ltd | D44: Mid Cap | E44: Bullish | F44: Watchlist | G44: High-performance computing (HPC) & NVIDIA AI server orders
...
